<mujoco>
  <worldbody>
    <body name="Htorso" pos="0 0 0.5">
      <joint armature="0" damping="0" limited="false" margin="0.01" name="Hroot" pos="0 0 0" type="free"/>
      <geom fromto="0.18 0.0 0.0  0.282 0.0 0.041" name="Hbeak" size="0.005" type="capsule" rgba="0.6 0.0 0.0 1"/>
      <geom fromto="0.18 +0.01 0.0  0.28 0.0 0.04" size="0.003" type="capsule" rgba="0.6 0.0 0.0 1"/>
      <geom fromto="0.18 -0.01 0.0  0.28 0.0 0.04" size="0.003" type="capsule" rgba="0.6 0.0 0.0 1"/>
      <geom fromto="0.18 +0.005 0.0  0.28 0.0 0.04" size="0.004" type="capsule" rgba="0.6 0.0 0.0 1"/>
      <geom fromto="0.18 -0.005 0.0  0.28 0.0 0.04" size="0.004" type="capsule" rgba="0.6 0.0 0.0 1"/>

      <camera name="Hview" mode="fixed" pos="0.2 +0 0.05" xyaxes="0 -1 0 0 0 1" fovy="120" />
      <geom pos="0.07 +0 0.07" name="HgviewL" size="0.01 0.03 0.03" type="box" rgba="0.14 0.14 0.14 1"/>
      <geom pos="0.06 +0 0.07" name="HgviewL1" size="0.025" type="sphere" rgba="0.1 0.1 0.1 1"/>

      <site name="Himu" />

      <geom name="Htorso_geom" pos="0 0 0.0" size="0.189 0.189 0.05" density="25" type="ellipsoid" rgba="0.9 0.2 0.2 1"/>

      <body name="Hfront_center_leg" pos="0.16 0 -0.0398">
        <geom name="Haux_1_geom" size="0.01" type="sphere"/>
        <body name="Haux_1" pos="0 0 0">
          <joint axis="0 1 0" pos="0.0 0.0 0.0" damping="0" type="hinge"/>
          <geom name="Hfleg_geom" size="0.01" type="sphere"  />
          <body name="Haux_12" pos="0 0 0">
            <joint axis="1 0 0" pos="0.0 0.0 0.0" damping="0" type="hinge"/>
            <geom name="Hfleg_geom2" size="0.02" type="sphere"  friction="0" material="wheels" />
          </body>
        </body>
      </body>
      <body name="Hback_center_leg" pos="-0.16 0 -0.0398">
        <geom name="Hbaux_1_geom" size="0.01" type="sphere"/>
        <body name="Hbaux_1" pos="0 0 0">
          <joint axis="0 1 0" pos="0.0 0.0 0.0" damping="0" type="hinge"/>
          <geom name="Hbleg_geom" size="0.01" type="sphere"  />
          <body name="Hbaux_12" pos="0 0 0">
            <joint axis="1 0 0" pos="0.0 0.0 0.0" damping="0" type="hinge"/>
            <geom name="Hbleg_geom2" size="0.02" type="sphere"  friction="0" material="wheels" />
          </body>
        </body>
      </body>

      <body name="Hleft_leg" pos="0 0.2 0">
        <geom rgba="0 0.45 0 1" name="Haux_2_geom" size="0.01" type="sphere"/>
        <body name="Haux_2" pos="0 0 0">
          <joint axis="0 1 0" name="Hjoint_bl" pos="0 0 0" type="hinge"/>
          <geom name="Hbleft_leg_geom" size="0.06 0.008 0.06" type="ellipsoid" friction="1" material="wheels" />
        </body>
      </body>

      <body name="Hright_leg" pos="0 -0.2 0">
        <geom rgba="0 0.45 0 1" name="Haux_3_geom" size="0.01" type="sphere" material="wheels" />
        <body name="Haux_3" pos="0 0 0">
          <joint axis="0 1 0" name="Hjoint_br" pos="0 0 0" type="hinge"/>
          <geom name="Hright_leg_geom" size="0.06 0.008 0.06" type="ellipsoid" friction="1" material="wheels" />
        </body>
      </body>
    </body>
  </worldbody>

  <actuator>
    <velocity joint="Hjoint_bl" kv="100" ctrllimited="true" ctrlrange="-30 30"/>
    <velocity joint="Hjoint_br" kv="100" ctrllimited="true" ctrlrange="-30 30"/>
  </actuator>
</mujoco>